<?xml version="1.0"?>
<sdf version="1.4">
  <world name="default">
    <include>
      <uri>model://ground_plane</uri>
    </include>

    <include>
      <uri>model://sun</uri>
    </include>

    <model name="IFV">
      <static>false</static>
      <pose>0 0 -0.05 0 0 0</pose>
<!- -----------------------BODY-------------------- ->

      <link name='chassis'>
        <pose>0 0 0.3 0 0 0</pose>
        <inertial>
        <mass>0.24</mass>
        <inertia>
          <ixx>0.002</ixx>
          <iyy>0.0034</iyy>
          <izz>0.005</izz>
        </inertia>
        </inertial>
        <collision name='bodyc'>
          <pose>0 0 0 0 0 0</pose>
          <geometry>
            <box>
              <size>.4 .3 .1</size>
            </box>
          </geometry>
        </collision>

        <visual name='bodyv'>
          <pose>0 0 0 0 0 0</pose>
          <geometry>
            <box>
              <size>.4 .3 .1</size>
            </box>
          </geometry>
        </visual>
            
        <collision name='camerac'>
          <pose>0.125 0 0.05 0 0 0</pose>
          <geometry>
            <sphere>
              <radius>.05</radius>
            </sphere>
          </geometry>
        </collision>

        <visual name='camerav'>
          <pose>0.125 0 0.05 0 0 0</pose>
          <geometry>
            <sphere>
              <radius>.05</radius>
            </sphere>
         </geometry>
        </visual>
      </link>

<!- ---------------LF leg----------------- ->
      <link name="LF_thigh">
        <pose>0.15 0.16 0.25 0 0 0</pose>
        <inertial>
          <mass>0.03</mass>
          <inertia>
            <ixx>0.00005725</ixx>
            <iyy>0.0000625</iyy>
            <izz>0.00000725</izz>
          </inertia>
        </inertial>
        <collision name='collision'>
          <geometry>
            <box>
              <size>.05 .02 .15</size>
            </box>
          </geometry>
        </collision>

        <visual name='visual'>
          <geometry>
            <box>
              <size>.05 .02 .15</size>
            </box>
          </geometry>
        </visual>
      </link>   
      <link name="LF_calf">
        <pose>0.15 0.18 0.15 0 0 0</pose>
        <inertial>
          <mass>0.024</mass>
          <inertia>
            <ixx>0.0000458</ixx>
            <iyy>0.0000482</iyy>
            <izz>0.000004</izz>
          </inertia>
        </inertial>
        <collision name='collision'>
          <geometry>
            <box>
              <size>.04 .02 .15</size>
            </box>
          </geometry>
        </collision>

        <visual name='visual'>
          <geometry>
            <box>
              <size>.04 .02 .15</size>
            </box>
          </geometry>
        </visual>
        <collision name='feetc'>
          <pose>0 0 -0.075 1.57079632679 0 0</pose>
          <geometry>
            <sphere>
                <radius>0.02</radius>
            </sphere>
          </geometry>
          <surface>
            <friction>
              <ode>
                <mu>100</mu>
                <mu2>100</mu2>
                <slip1>0</slip1>
                <slip2>0</slip2>
              </ode>
            </friction>
            <contact>
              <ode>
                <kd>1000000</kd>
              </ode>
            </contact> 
          </surface>
        </collision>
        <visual name='feetv'>
          <pose>0 0 -0.075 1.57079632679 0 0</pose>
          <geometry>
            <sphere>
                <radius>0.02</radius>
            </sphere>
          </geometry>
        </visual>
      </link>

<!- --------------------RF leg------------------- ->
      <link name="RF_thigh">
        <pose>0.15 -0.16 0.25 0 0 0</pose>
        <inertial>
          <mass>0.03</mass>
          <inertia>
            <ixx>0.00005725</ixx>
            <iyy>0.0000625</iyy>
            <izz>0.00000725</izz>
          </inertia>
        </inertial>
            <collision name='collision'>
              <geometry>
                <box>
                  <size>.05 .02 .15</size>
                </box>
              </geometry>
            </collision>

            <visual name='visual'>
              <geometry>
                <box>
                  <size>.05 .02 .15</size>
                </box>
              </geometry>
            </visual>
      </link>   
      <link name="RF_calf">
        <pose>0.15 -0.18 0.15 0 0 0</pose>
        <inertial>
          <mass>0.024</mass>
          <inertia>
            <ixx>0.0000458</ixx>
            <iyy>0.0000482</iyy>
            <izz>0.000004</izz>
          </inertia>
        </inertial>
        <collision name='collision'>
              <geometry>
                <box>
                  <size>.04 .02 .15</size>
                </box>
              </geometry>
            </collision>

            <visual name='visual'>
              <geometry>
                <box>
                  <size>.04 .02 .15</size>
                </box>
              </geometry>
            </visual>
            <collision name='feetc'>
          <pose>0 0 -0.075 1.57079632679 0 0</pose>
          <geometry>
            <sphere>
                <radius>0.02</radius>
            </sphere>
          </geometry>
          <surface>
            <friction>
              <ode>
                <mu>100</mu>
                <mu2>100</mu2>
                <slip1>0</slip1>
                <slip2>0</slip2>
              </ode>
            </friction>
            <contact>
              <ode>
                <kd>1000000</kd>
              </ode>
            </contact>    
          </surface>
        </collision>
        <visual name='feetv'>
          <pose>0 0 -0.075 1.57079632679 0 0</pose>
          <geometry>
            <sphere>
                <radius>0.02</radius>
            </sphere>
          </geometry>
        </visual>
      </link>
<!- -------------------LH leg-------------------- ->
      <link name="LH_thigh">
        <pose>-0.15 0.16 0.25 0 0 0</pose>
        <inertial>
          <mass>0.03</mass>
          <inertia>
            <ixx>0.00005725</ixx>
            <iyy>0.0000625</iyy>
            <izz>0.00000725</izz>
          </inertia>
        </inertial>
        <collision name='collision'>
              <geometry>
                <box>
                  <size>.05 .02 .15</size>
                </box>
              </geometry>
        </collision>

        <visual name='visual'>
              <geometry>
                <box>
                  <size>.05 .02 .15</size>
                </box>
              </geometry>
            </visual>
      </link>   
      <link name="LH_calf">
        <pose>-0.15 0.18 0.15 0 0 0</pose>
        <inertial>
          <mass>0.024</mass>
          <inertia>
            <ixx>0.0000458</ixx>
            <iyy>0.0000482</iyy>
            <izz>0.000004</izz>
          </inertia>
        </inertial>
        <collision name='collision'>
              <geometry>
                <box>
                  <size>.04 .02 .15</size>
                </box>
              </geometry>
            </collision>

            <visual name='visual'>
              <geometry>
                <box>
                  <size>.04 .02 .15</size>
                </box>
              </geometry>
            </visual>
            <collision name='feetc'>
          <pose>0 0 -0.075 1.57079632679 0 0</pose>
          <geometry>
            <sphere>
                <radius>0.02</radius>
            </sphere>
          </geometry>
          <surface>
            <friction>
              <ode>
                <mu>100</mu>
                <mu2>100</mu2>
                <slip1>0</slip1>
                <slip2>0</slip2>
              </ode>
            </friction>
            <contact>
              <ode>
                <kd>1000000</kd>
              </ode>
            </contact> 
          </surface>
        </collision>
        <visual name='feetv'>
          <pose>0 0 -0.075 1.57079632679 0 0</pose>
          <geometry>
            <sphere>
                <radius>0.02</radius>
            </sphere>
          </geometry>
        </visual>
      </link>
<!- -------------------RH leg-------------------- ->
      <link name="RH_thigh">
        <pose>-0.15 -0.16 0.25 0 0 0</pose>
        <inertial>
          <mass>0.03</mass>
          <inertia>
            <ixx>0.00005725</ixx>
            <iyy>0.0000625</iyy>
            <izz>0.00000725</izz>
          </inertia>
        </inertial>
        <collision name='collision'>
              <geometry>
                <box>
                  <size>.05 .02 .15</size>
                </box>
              </geometry>
        </collision>

        <visual name='visual'>
              <geometry>
                <box>
                  <size>.04 .02 .15</size>
                </box>
              </geometry>
        </visual>
      </link> 
      <link name="RH_calf">
        <pose>-0.15 -0.18 0.15 0 0 0</pose>
        <inertial>
          <mass>0.024</mass>
          <inertia>
            <ixx>0.0000458</ixx>
            <iyy>0.0000482</iyy>
            <izz>0.000004</izz>
          </inertia>
        </inertial>
        <collision name='collision'>
              <geometry>
                <box>
                  <size>.04 .02 .15</size>
                </box>
              </geometry>
            </collision>

            <visual name='visual'>
              <geometry>
                <box>
                  <size>.04 .02 .15</size>
                </box>
              </geometry>
            </visual>
        <collision name='feetc'>
          <pose>0 0 -0.075 1.57079632679 0 0</pose>
          <geometry>
            <sphere>
                <radius>0.02</radius>
            </sphere>
          </geometry>
          <surface>
            <friction>
              <ode>
                <mu>100</mu>
                <mu2>100</mu2>
                <slip1>0</slip1>
                <slip2>0</slip2>
              </ode>
            </friction>
            <contact>
              <ode>
                <kd>1000000</kd>
              </ode>
            </contact> 
          </surface>
        </collision>
        <visual name='feetv'>
          <pose>0 0 -0.075 1.57079632679 0 0</pose>
          <geometry>
            <sphere>
                <radius>0.02</radius>
            </sphere>
          </geometry>
        </visual>
      </link>
      <joint type="revolute" name="LF_body2thigh">
        <pose>0 0 0.05 0 0 0</pose>
        <child>LF_thigh</child>
        <parent>chassis</parent>
        <axis>
          <xyz>0 1 0</xyz>
          <limit>
            <effort>20</effort> 
            <lower>1.0471975512</lower>
            <upper>0.872664625997</upper>
            <velocity>52.4</velocity>
          </limit>
        </axis>
      </joint>

      <joint type="revolute" name="LF_thigh2calf">
        <pose>0 0 0.05 0 0 0</pose>
        <child>LF_calf</child>
        <parent>LF_thigh</parent>
        <axis>
          <xyz>0 1 0</xyz>
          <limit>
            <effort>55</effort> 
            <lower>2.77507351067</lower>
            <upper>0.61086523819</upper>
            <velocity>28.6</velocity>
          </limit>
        </axis>
      </joint>

      <joint type="revolute" name="RF_body2thigh">
        <pose>0 0 0.05 0 0 0</pose>
        <child>RF_thigh</child>
        <parent>chassis</parent>
        <axis>
          <xyz>0 1 0</xyz>
          <limit>
            <effort>20</effort> 
            <lower>1.0471975512</lower>
            <upper>0.872664625997</upper>
            <velocity>52.4</velocity>
          </limit>
        </axis>
        
      </joint>

      <joint type="revolute" name="RF_thigh2calf">
        <pose>0 0 0.05 0 0 0</pose>
        <child>RF_calf</child>
        <parent>RF_thigh</parent>
        <axis>
          <xyz>0 1 0</xyz>
      
          <limit>
            <effort>55</effort> 
            <lower>2.77507351067</lower>
            <upper>0.61086523819</upper>
            <velocity>28.6</velocity>
          </limit>
        </axis>
        
      </joint>
      <joint type="revolute" name="LH_body2thigh">
        <pose>0 0 0.05 0 0 0</pose>
        <child>LH_thigh</child>
        <parent>chassis</parent>
        <axis>
          <xyz>0 1 0</xyz>
          <limit>
            <effort>20</effort> 
            <lower>1.0471975512</lower>
            <upper>0.872664625997</upper>
            <velocity>52.4</velocity>
          </limit>
        </axis>
        
      </joint>

      <joint type="revolute" name="LH_thigh2calf">
        <pose>0 0 0.05 0 0 0</pose>
        <child>LH_calf</child>
        <parent>LH_thigh</parent>
        <axis>
          <xyz>0 1 0</xyz>
          
          <limit>
            <effort>55</effort> 
            <lower>2.77507351067</lower>
            <upper>0.61086523819</upper>
            <velocity>28.6</velocity>
          </limit>
        </axis>
        
      </joint>

      <joint type="revolute" name="RH_body2thigh">
        <pose>0 0 0.05 0 0 0</pose>
        <child>RH_thigh</child>
        <parent>chassis</parent>
        <axis>
          <xyz>0 1 0</xyz>
          
          <limit>
            <effort>20</effort> 
            <lower>1.0471975512</lower>
            <upper>0.872664625997</upper>
            <velocity>52.4</velocity>
          </limit>
        </axis>
        
      </joint>

      <joint type="revolute" name="RH_thigh2calf">
        <pose>0 0 0.05 0 0 0</pose>
        <child>RH_calf</child>
        <parent>RH_thigh</parent>
        <axis>
          <xyz>0 1 0</xyz>
          <limit>
            <effort>55</effort> 
            <lower>2.77507351067</lower>
            <upper>0.61086523819</upper>
            <velocity>28.6</velocity>
          </limit>
        </axis>
        
      </joint>
      
      <plugin name="gazebo_ros_joint_state_publisher"
        filename="libgazebo_ros_joint_state_publisher.so">

      <ros>

        <!-- Add a namespace -->
        <namespace>/IFV</namespace>

        <!-- Remap the default topic -->
        <remapping>joint_states:=my_joint_states</remapping>

      </ros>

      <!-- Update rate in Hertz -->
      <update_rate>500</update_rate>

      <!-- Name of joints in the model whose states will be published. -->
      <joint_name>LF_body2thigh</joint_name>
      <joint_name>LF_thigh2calf</joint_name>
      <joint_name>RF_body2thigh</joint_name>
      <joint_name>RF_thigh2calf</joint_name>
      <joint_name>LH_body2thigh</joint_name>
      <joint_name>LH_thigh2calf</joint_name>
      <joint_name>RH_body2thigh</joint_name>
      <joint_name>RH_thigh2calf</joint_name>

      </plugin>
      <plugin name="applytorque"
        filename="/home/longarmape06/ifv_ws/src/build/ifv_pkg/libapplytorque.so">
      </plugin>
    </model>  

  </world>
</sdf>
